Workbook

Sheet ReadMe
B3: International Monetary Fund
B4: Monetary and Capital Markets Department
B10: Sovereign Debt Investor Base for Advanced Economies
B11: Regularly updated at end-April and end-October
B12: (This Version: Nov 1, 2024)
B13: Note: Data for 2023 are preliminary and subject to change. In 2019, the dataset was extended to all advanced economies with annual data going back to 1989, where feasible (see "ExtendedDataset" worksheet). The methodology follows Arslanalp and Tsuda (2014) with additional source data. For any questions, please contact Serkan Arslanalp (sarslanalp@imf.org) and Takahiro Tsuda (takahiro.tsuda@mof.go.jp).
B17: Database weblink: | C17: https://www.imf.org/~/media/Websites/IMF/imported-datasets/external/pubs/ft/wp/2012/Data/_wp12284.ashx
B19: Data Sources: | C19: Primary data sources include: Bank for International Settlements International Banking Statistics; ECB; Eurostat; IMF International Financial Statistics (IFS); IMF Coordinated Portfolio Investment Survey (CPIS); IMF Currency Composition of Official Foreign Exchange Reserves (COFER); IMF-World Bank Quarterly External Debt Statistics. Where applicable, national data sources are used.
B21: Data description | C21: The dataset provides estimates of investor holdings of general government debt of 24 advanced economies. The investor base is grouped under six classes: domestic central bank, domestic banks, domestic nonbanks, foreign official sector, foreign banks, and foreign nonbanks. All data are either in face value or adjusted for valuation changes, where appropriate, to remove price revaluations. All intra-governmental holdings are netted out. All figures are in billions of national currency. ECB data are used for the calculation of domestic central bank and domestic bank holdings of sovereign debt for eurozone countries.
B23: Sample period | C23: 1989:Q4 - 2024:Q2
B26: Authors | C26: The database was assembled by Serkan Arslanalp and Takahiro Tsuda, previously affiliated with the Monetary and Capital Markets Department of the International Monetary Fund.
B29: Published paper/reference: | C29: http://www.palgrave-journals.com/imfer/journal/v62/n3/pdf/imfer201420a.pdf
C31: Arslanalp S. and T. Tsuda, 2014, "Tracking Global Demand for Advanced Economy Sovereign Debt" IMF Economic Review, Volume 62, Number 3, Washington DC.
B32: Working paper/reference: | C32: http://www.imf.org/external/pubs/ft/wp/2012/wp12284.pdf
C33: The dataset can be quoted as "Sovereign investor base estimates by Arslanalp and Tsuda (2014)". The full reference is: Arslanalp S. and T. Tsuda, 2014, "Tracking Global Demand for Advanced Economy Sovereign Debt" IMF Economic Review, Volume 62, Number 3, Washington DC. An earlier version was published as: Serkan Arslanalp and Takahiro Tsuda (2012) "Tracking Global Demand for Advanced Economy Sovereign Debt", IMF Working Paper WP/12/284, Washington, DC.
B37: Date of last update: | C37: Nov 1, 2024.
B39: Note: | C39: Subject to changes due to data revisions.
B41: Contact information | C41: Please send your comments and queries to Serkan Arslanalp (sarslanalp@imf.org) and Takahiro Tsuda (takahiro.tsuda@mof.go.jp).
B46: Contents (all figures are presented in billions of national currency):
B47: Total General Government Gross Debt, on a consolidated basis 1/…………………………………….……………………….. | J47: Table 1
B49: General Government Gross Debt held by Foreign Investors 1/…………………………………………………………………………… | J49: Table 2
B51: General Government Gross Debt held by Foreign Official Sector 1/…………………………………………………………. | J51: Table 2.1
B52: General Government Gross Debt held by Foreign Banks…………………………………………………………………. | J52: Table 2.2
B53: General Government Gross Debt held by Foreign Nonbanks…………………………………………………………….. | J53: Table 2.3
B55: General Government Gross Debt held by Domestic Investors 1/………………………………………………………………………… | J55: Table 3
B57: General Government Gross Debt held by Domestic Central Bank……………………………………………………….. | J57: Table 3.1
B58: General Government Gross Debt held by Domestic Banks………………………………………………………………. | J58: Table 3.2
B59: General Government Gross Debt held by Domestic Nonbanks………………………………………………………….. | J59: Table 3.3
B61: 1/ For these series, estimates are also provided for general government debt securities.

Sheet ExtendedDataset
A1: Total (Billion LC) | B1: 1989 | C1: =B1+1 -> 1990 | D1: =C1+1 -> 1991 | E1: =D1+1 -> 1992 | F1: =E1+1 -> 1993 | G1: =F1+1 -> 1994 | H1: =G1+1 -> 1995 | I1: =H1+1 -> 1996 | J1: =I1+1 -> 1997 | ... AJ1: =AI1+1 -> 2023
A2: Australia | B2: 82.168 | C2: 85.056 | D2: 100.853 | E2: 121.104 | F2: 146.331 | G2: 166.042 | H2: 173.557 | I2: 166.858 | J2: 154.004 | K2: 143.471 | L2: 132.632 | M2: 115.578 | N2: 111.529 | O2: 105.476 | P2: 101.269 | Q2: ='Table 1. Total'!E2 -> 98.371 | R2: ='Table 1. Total'!I2 -> 95.67 | S2: ='Table 1. Total'!M2 -> 94.371 | T2: ='Table 1. Total'!Q2 -> 101.98 | U2: ='Table 1. Total'!U2 -> 139.455 | V2: ='Table 1. Total'!Y2 -> 197.87 | W2: ='Table 1. Total'!AC2 -> 255.388 | X2: ='Table 1. Total'!AG2 -> 327.225 | Y2: ='Table 1. Total'!AK2 -> 381.15 | Z2: ='Table 1. Total'!AO2 -> 439.698 | AA2: ='Table 1. Total'!AS2 -> 503.236 | AB2: ='Table 1. Total'!AW2 -> 559.156 | AC2: ='Table 1. Total'!BA2 -> 621.359 | AD2: ='Table 1. Total'!BE2 -> 682.677 | AE2: ='Table 1. Total'!BI2 -> 711.617 | AF2: ='Table 1. Total'!BM2 -> 811.364 | AG2: ='Table 1. Total'!BQ2 -> 1039.316 | AH2: ='Table 1. Total'!BU2 -> 1185.387 | AI2: ='Table 1. Total'!BY2 -> 1268.571 | AJ2: ='Table 1. Total'!CC2 -> 1313.062
A3: Austria | B3: 70.1 | C3: 74.1 | D3: 80 | E3: 87.8 | F3: 99.3 | G3: 111.2 | H3: 125.3 | I3: 125.2 | J3: 118.6 | K3: 125.4 | L3: 135.9 | M3: 141.543 | N3: 147.503 | O3: 151.8 | P3: 153.107 | Q3: ='Table 1. Total'!E3 -> 158.546 | R3: ='Table 1. Total'!I3 -> 175.204 | S3: ='Table 1. Total'!M3 -> 181.304 | T3: ='Table 1. Total'!Q3 -> 185.73 | U3: ='Table 1. Total'!U3 -> 202.915 | V3: ='Table 1. Total'!Y3 -> 231.173 | W3: ='Table 1. Total'!AC3 -> 245.985 | X3: ='Table 1. Total'!AG3 -> 256.876 | Y3: ='Table 1. Total'!AK3 -> 262.565 | Z3: ='Table 1. Total'!AO3 -> 264.761 | AA3: ='Table 1. Total'!AS3 -> 281.289 | AB3: ='Table 1. Total'!AW3 -> 292.874 | AC3: ='Table 1. Total'!BA3 -> 296.693 | AD3: ='Table 1. Total'!BE3 -> 290.373 | AE3: ='Table 1. Total'!BI3 -> 285.84 | AF3: ='Table 1. Total'!BM3 -> 280.975 | AG3: ='Table 1. Total'!BQ3 -> 316.36 | AH3: ='Table 1. Total'!BU3 -> 334.713 | AI3: ='Table 1. Total'!BY3 -> 351.129 | AJ3: ='Table 1. Total'!CC3 -> 371.729
A4: Belgium | B4: 186.6 | C4: 206 | D4: 219.4 | E4: 243.5 | F4: 260.9 | G4: 278.7 | H4: 288.1 | I4: 278.1 | J4: 275.6 | K4: 277.3 | L4: 279.5 | M4: 280.96 | N4: 286.055 | O4: 288.111 | P4: 285.867 | Q4: ='Table 1. Total'!E4 -> 288.419 | R4: ='Table 1. Total'!I4 -> 294.975 | S4: ='Table 1. Total'!M4 -> 297.495 | T4: ='Table 1. Total'!Q4 -> 300.064 | U4: ='Table 1. Total'!U4 -> 327.683 | V4: ='Table 1. Total'!Y4 -> 347.224 | W4: ='Table 1. Total'!AC4 -> 364.132 | X4: ='Table 1. Total'!AG4 -> 389.107 | Y4: ='Table 1. Total'!AK4 -> 404.752 | Z4: ='Table 1. Total'!AO4 -> 414.476 | AA4: ='Table 1. Total'!AS4 -> 431.464 | AB4: ='Table 1. Total'!AW4 -> 438.657 | AC4: ='Table 1. Total'!BA4 -> 451.818 | AD4: ='Table 1. Total'!BE4 -> 454.282 | AE4: ='Table 1. Total'!BI4 -> 459.669 | AF4: ='Table 1. Total'!BM4 -> 467.534 | AG4: ='Table 1. Total'!BQ4 -> 515.53 | AH4: ='Table 1. Total'!BU4 -> 548.775 | AI4: ='Table 1. Total'!BY4 -> 578.336 | AJ4: ='Table 1. Total'!CC4 -> 614.991
A5: Canada | B5: 498.232 | C5: 540.566 | D5: 596.721 | E5: 651.177 | F5: 714.637 | G5: 769.362 | H5: 809.808 | I5: 830.255 | J5: 827.563 | K5: 832.022 | L5: 847.73 | M5: 839.749 | N5: 848.993 | O5: 871.956 | P5: 868.112 | Q5: ='Table 1. Total'!E5 -> 871.456 | R5: ='Table 1. Total'!I5 -> 879.686 | S5: ='Table 1. Total'!M5 -> 896.041 | T5: ='Table 1. Total'!Q5 -> 890.993 | U5: ='Table 1. Total'!U5 -> 1012.48 | V5: ='Table 1. Total'!Y5 -> 1154.954 | W5: ='Table 1. Total'!AC5 -> 1244.007 | X5: ='Table 1. Total'!AG5 -> 1336.885 | Y5: ='Table 1. Total'!AK5 -> 1427.99 | Z5: ='Table 1. Total'!AO5 -> 1508.667 | AA5: ='Table 1. Total'!AS5 -> 1531.127 | AB5: ='Table 1. Total'!AW5 -> 1635.591 | AC5: ='Table 1. Total'!BA5 -> 1674.636 | AD5: ='Table 1. Total'!BE5 -> 1743.514 | AE5: ='Table 1. Total'!BI5 -> 1813.879 | AF5: ='Table 1. Total'!BM5 -> 1882.054 | AG5: ='Table 1. Total'!BQ5 -> 2354.228 | AH5: ='Table 1. Total'!BU5 -> 2548.598 | AI5: ='Table 1. Total'!BY5 -> 2629.466 | AJ5: ='Table 1. Total'!CC5 -> 2753.325
A6: Czech Republic | B6: … | C6: … | D6: … | E6: … | F6: … | G6: … | H6: 216.6 | I6: 211.8 | J6: 240.3 | K6: 301 | L6: 342.1 | M6: 405.418 | N6: 585.615 | O6: 695.133 | P6: 795.04 | Q6: ='Table 1. Total'!E6 -> 873.493 | R6: ='Table 1. Total'!I6 -> 910.183 | S6: ='Table 1. Total'!M6 -> 973.107 | T6: ='Table 1. Total'!Q6 -> 1054.633 | U6: ='Table 1. Total'!U6 -> 1136.774 | V6: ='Table 1. Total'!Y6 -> 1319.002 | W6: ='Table 1. Total'!AC6 -> 1480.097 | X6: ='Table 1. Total'!AG6 -> 1613.65 | Y6: ='Table 1. Total'!AK6 -> 1805.307 | Z6: ='Table 1. Total'!AO6 -> 1840.247 | AA6: ='Table 1. Total'!AS6 -> 1818.888 | AB6: ='Table 1. Total'!AW6 -> 1836.047 | AC6: ='Table 1. Total'!BA6 -> 1754.737 | AD6: ='Table 1. Total'!BE6 -> 1749.677 | AE6: ='Table 1. Total'!BI6 -> 1734.602 | AF6: ='Table 1. Total'!BM6 -> 1740.263 | AG6: ='Table 1. Total'!BQ6 -> 2149.655 | AH6: ='Table 1. Total'!BU6 -> 2566.752 | AI6: ='Table 1. Total'!BY6 -> 2997.632 | AJ6: ='Table 1. Total'!CC6 -> 3234.002
A7: Denmark | B7: 511.4 | C7: 533.9 | D7: 562.7 | E7: 631.4 | F7: 747.9 | G7: 765.6 | H7: 758 | I7: 760.8 | J7: 754.7 | K7: 732.4 | L7: 722 | M7: 710.098 | N7: 687.462 | O7: 710.254 | P7: 693.004 | Q7: ='Table 1. Total'!E7 -> 697.698 | R7: ='Table 1. Total'!I7 -> 625.854 | S7: ='Table 1. Total'!M7 -> 559.349 | T7: ='Table 1. Total'!Q7 -> 513.925 | U7: ='Table 1. Total'!U7 -> 643.16 | V7: ='Table 1. Total'!Y7 -> 744.541 | W7: ='Table 1. Total'!AC7 -> 836.167 | X7: ='Table 1. Total'!AG7 -> 924.011 | Y7: ='Table 1. Total'!AK7 -> 922.073 | Z7: ='Table 1. Total'!AO7 -> 924.613 | AA7: ='Table 1. Total'!AS7 -> 964.634 | AB7: ='Table 1. Total'!AW7 -> 904.464 | AC7: ='Table 1. Total'!BA7 -> 876.165 | AD7: ='Table 1. Total'!BE7 -> 879.176 | AE7: ='Table 1. Total'!BI7 -> 864.633 | AF7: ='Table 1. Total'!BM7 -> 883.091 | AG7: ='Table 1. Total'!BQ7 -> 1076.709 | AH7: ='Table 1. Total'!BU7 -> 1039.517 | AI7: ='Table 1. Total'!BY7 -> 969.223 | AJ7: ='Table 1. Total'!CC7 -> 942.073
A8: Finland | B8: 15 | C8: 15.1 | D8: 20.4 | E8: 31.2 | F8: 42.7 | G8: 52 | H8: 56.5 | I8: 57.7 | J8: 57.5 | K8: 56.4 | L8: 55.9 | M8: 61.564 | N8: 62.825 | O8: 63.299 | P8: 68.508 | Q8: ='Table 1. Total'!E8 -> 71.335 | R8: ='Table 1. Total'!I8 -> 69.397 | S8: ='Table 1. Total'!M8 -> 69.532 | T8: ='Table 1. Total'!Q8 -> 67.34 | U8: ='Table 1. Total'!U8 -> 67.435 | V8: ='Table 1. Total'!Y8 -> 80.2 | W8: ='Table 1. Total'!AC8 -> 94.286 | X8: ='Table 1. Total'!AG8 -> 102.829 | Y8: ='Table 1. Total'!AK8 -> 115.931 | Z8: ='Table 1. Total'!AO8 -> 123.75 | AA8: ='Table 1. Total'!AS8 -> 133.42 | AB8: ='Table 1. Total'!AW8 -> 144.537 | AC8: ='Table 1. Total'!BA8 -> 148.088 | AD8: ='Table 1. Total'!BE8 -> 149.611 | AE8: ='Table 1. Total'!BI8 -> 151.569 | AF8: ='Table 1. Total'!BM8 -> 155.827 | AG8: ='Table 1. Total'!BQ8 -> 178.148 | AH8: ='Table 1. Total'!BU8 -> 182.213 | AI8: ='Table 1. Total'!BY8 -> 197.022 | AJ8: ='Table 1. Total'!CC8 -> 210.866
A9: France | B9: 334.1 | C9: 362.9 | D9: 384.2 | E9: 457.8 | F9: 543.5 | G9: 601.3 | H9: 714.7 | I9: 755.3 | J9: 793 | K9: 836.1 | L9: 856.9 | M9: 880.005 | N9: 907.673 | O9: 966.823 | P9: 1060.406 | Q9: ='Table 1. Total'!E9 -> 1134.347 | R9: ='Table 1. Total'!I9 -> 1201.471 | S9: ='Table 1. Total'!M9 -> 1207.313 | T9: ='Table 1. Total'!Q9 -> 1268.859 | U9: ='Table 1. Total'!U9 -> 1389.402 | V9: ='Table 1. Total'!Y9 -> 1627.182 | W9: ='Table 1. Total'!AC9 -> 1722.172 | X9: ='Table 1. Total'!AG9 -> 1830.136 | Y9: ='Table 1. Total'!AK9 -> 1915.835 | Z9: ='Table 1. Total'!AO9 -> 2004.704 | AA9: ='Table 1. Total'!AS9 -> 2070.579 | AB9: ='Table 1. Total'!AW9 -> 2134.071 | AC9: ='Table 1. Total'!BA9 -> 2190.007 | AD9: ='Table 1. Total'!BE9 -> 2262.443 | AE9: ='Table 1. Total'!BI9 -> 2319.775 | AF9: ='Table 1. Total'!BM9 -> 2386.133 | AG9: ='Table 1. Total'!BQ9 -> 2662.105 | AH9: ='Table 1. Total'!BU9 -> 2826.726 | AI9: ='Table 1. Total'!BY9 -> 2953.624 | AJ9: ='Table 1. Total'!CC9 -> 3101.376
A10: Germany | B10: 464.9 | C10: 527.5 | D10: 590.1 | E10: 701.1 | F10: 794.2 | G10: 888.2 | H10: 1079.9 | I10: 1115.7 | J10: 1142.5 | K10: 1199.3 | L10: 1243.7 | M10: 1261.585 | N10: 1274.759 | O10: 1330.083 | P10: 1419.426 | Q10: ='Table 1. Total'!E10 -> 1489.671 | R10: ='Table 1. Total'!I10 -> 1561.021 | S10: ='Table 1. Total'!M10 -> 1610.904 | T10: ='Table 1. Total'!Q10 -> 1619.065 | U10: ='Table 1. Total'!U10 -> 1687.442 | V10: ='Table 1. Total'!Y10 -> 1804.696 | W10: ='Table 1. Total'!AC10 -> 2119.242 | X10: ='Table 1. Total'!AG10 -> 2155.876 | Y10: ='Table 1. Total'!AK10 -> 2234.803 | Z10: ='Table 1. Total'!AO10 -> 2220.281 | AA10: ='Table 1. Total'!AS10 -> 2224.56 | AB10: ='Table 1. Total'!AW10 -> 2197.474 | AC10: ='Table 1. Total'!BA10 -> 2182.375 | AD10: ='Table 1. Total'!BE10 -> 2132.784 | AE10: ='Table 1. Total'!BI10 -> 2086.445 | AF10: ='Table 1. Total'!BM10 -> 2075.012 | AG10: ='Table 1. Total'!BQ10 -> 2346.955 | AH10: ='Table 1. Total'!BU10 -> 2502.817 | AI10: ='Table 1. Total'!BY10 -> 2569.897 | AJ10: ='Table 1. Total'!CC10 -> 2631.777
A11: Greece | B11: 44.8 | C11: 52.5 | D11: 61 | E11: 68.1 | F11: 90 | G11: 94.1 | H11: 100.8 | I11: 115 | J11: 124.6 | K11: 126.1 | L11: 136.5 | M11: 148.217 | N11: 162.971 | O11: 171.41 | P11: 181.51 | Q11: ='Table 1. Total'!E11 -> 199.282 | R11: ='Table 1. Total'!I11 -> 213.976 | S11: ='Table 1. Total'!M11 -> 225.73 | T11: ='Table 1. Total'!Q11 -> 239.915 | U11: ='Table 1. Total'!U11 -> 264.775 | V11: ='Table 1. Total'!Y11 -> 301.062 | W11: ='Table 1. Total'!AC11 -> 330.57 | X11: ='Table 1. Total'!AG11 -> 356.235 | Y11: ='Table 1. Total'!AK11 -> 305.085 | Z11: ='Table 1. Total'!AO11 -> 321.257 | AA11: ='Table 1. Total'!AS11 -> 321.631 | AB11: ='Table 1. Total'!AW11 -> 314.987 | AC11: ='Table 1. Total'!BA11 -> 319.425 | AD11: ='Table 1. Total'!BE11 -> 323.004 | AE11: ='Table 1. Total'!BI11 -> 341.416 | AF11: ='Table 1. Total'!BM11 -> 339.201 | AG11: ='Table 1. Total'!BQ11 -> 350.798 | AH11: ='Table 1. Total'!BU11 -> 364.141 | AI11: ='Table 1. Total'!BY11 -> 368.005 | AJ11: ='Table 1. Total'!CC11 -> 369.099
A12: Ireland | B12: 34.8 | C12: 35.1 | D12: 37 | E12: 39.3 | F12: 41 | G12: 41.3 | H12: 41.3 | I12: 44.4 | J12: 43.6 | K12: 41.4 | L12: 43.2 | M12: 39.506 | N12: 40.995 | O12: 42.009 | P12: 43.429 | Q12: ='Table 1. Total'!E12 -> 43.914 | R12: ='Table 1. Total'!I12 -> 44.381 | S12: ='Table 1. Total'!M12 -> 43.739 | T12: ='Table 1. Total'!Q12 -> 47.195 | U12: ='Table 1. Total'!U12 -> 79.621 | V12: ='Table 1. Total'!Y12 -> 104.703 | W12: ='Table 1. Total'!AC12 -> 144.23 | X12: ='Table 1. Total'!AG12 -> 189.727 | Y12: ='Table 1. Total'!AK12 -> 210.026 | Z12: ='Table 1. Total'!AO12 -> 215.242 | AA12: ='Table 1. Total'!AS12 -> 203.381 | AB12: ='Table 1. Total'!AW12 -> 201.578 | AC12: ='Table 1. Total'!BA12 -> 200.635 | AD12: ='Table 1. Total'!BE12 -> 201.262 | AE12: ='Table 1. Total'!BI12 -> 205.848 | AF12: ='Table 1. Total'!BM12 -> 203.383 | AG12: ='Table 1. Total'!BQ12 -> 217.885 | AH12: ='Table 1. Total'!BU12 -> 236.127 | AI12: ='Table 1. Total'!BY12 -> 224.78 | AJ12: ='Table 1. Total'!CC12 -> 220.724
A13: Italy | B13: 754.9 | C13: 839.6 | D13: 947.8 | E13: 920.7 | F13: 972.9 | G13: 1036.7 | H13: 1096.6 | I13: 1260.4 | J13: 1271.9 | K13: 1299.7 | L13: 1331.3 | M13: 1353.569 | N13: 1420.027 | O13: 1436.142 | P13: 1471.326 | Q13: ='Table 1. Total'!E13 -> 1526.461 | R13: ='Table 1. Total'!I13 -> 1591.65 | S13: ='Table 1. Total'!M13 -> 1657.403 | T13: ='Table 1. Total'!Q13 -> 1677.725 | U13: ='Table 1. Total'!U13 -> 1738.851 | V13: ='Table 1. Total'!Y13 -> 1839.486 | W13: ='Table 1. Total'!AC13 -> 1921.1 | X13: ='Table 1. Total'!AG13 -> 1974.013 | Y13: ='Table 1. Total'!AK13 -> 2055.338 | Z13: ='Table 1. Total'!AO13 -> 2137.088 | AA13: ='Table 1. Total'!AS13 -> 2204.424 | AB13: ='Table 1. Total'!AW13 -> 2241.195 | AC13: ='Table 1. Total'!BA13 -> 2287.84 | AD13: ='Table 1. Total'!BE13 -> 2332.197 | AE13: ='Table 1. Total'!BI13 -> 2384.631 | AF13: ='Table 1. Total'!BM13 -> 2414.252 | AG13: ='Table 1. Total'!BQ13 -> 2576.629 | AH13: ='Table 1. Total'!BU13 -> 2685.173 | AI13: ='Table 1. Total'!BY13 -> 2762.908 | AJ13: ='Table 1. Total'!CC13 -> 2868.411
A14: Japan | B14: 222324.72 | C14: 230176.01 | D14: 241918.18 | E14: 265620.8 | F14: 289970.72 | G14: 336374.8 | H14: 387861.96 | I14: 419213.54 | J14: 449640.98 | K14: 499769.22 | L14: 560978.82 | M14: 614161.3 | N14: 647986.66 | O14: 667570.32 | P14: 717925.66 | Q14: ='Table 1. Total'!E14 -> 761502.46 | R14: ='Table 1. Total'!I14 -> 776591.23 | S14: ='Table 1. Total'!M14 -> 770922.57 | T14: ='Table 1. Total'!Q14 -> 766182.23 | U14: ='Table 1. Total'!U14 -> 765795.46 | V14: ='Table 1. Total'!Y14 -> 813270.64 | W14: ='Table 1. Total'!AC14 -> 863420.39 | X14: ='Table 1. Total'!AG14 -> 910512.03 | Y14: ='Table 1. Total'!AK14 -> 950146.14 | Z14: ='Table 1. Total'!AO14 -> 988964.92 | AA14: ='Table 1. Total'!AS14 -> 1029614 | AB14: ='Table 1. Total'!AW14 -> 1052524.6 | AC14: ='Table 1. Total'!BA14 -> 1079840.1 | AD14: ='Table 1. Total'!BE14 -> 1101997.4 | AE14: ='Table 1. Total'!BI14 -> 1115855 | AF14: ='Table 1. Total'!BM14 -> 1134597.1 | AG14: ='Table 1. Total'!BQ14 -> 1220382.9 | AH14: ='Table 1. Total'!BU14 -> 1220737.8 | AI14: ='Table 1. Total'!BY14 -> 1271760.7 | AJ14: ='Table 1. Total'!CC14 -> 1297630.5
A15: Korea | B15: … | C15: … | D15: … | E15: … | F15: … | G15: 26705.25 | H15: 26913.496 | I15: 27569.593 | J15: 45715.571 | K15: 62287.498 | L15: 76887.736 | M15: 85414.821 | N15: 92944.294 | O15: 96002.275 | P15: 110663.67 | Q15: ='Table 1. Total'!E15 -> 144708.15 | R15: ='Table 1. Total'!I15 -> 180193.7 | S15: ='Table 1. Total'!M15 -> 219155.53 | T15: ='Table 1. Total'!Q15 -> 233924.3 | U15: ='Table 1. Total'!U15 -> 264086.6 | V15: ='Table 1. Total'!Y15 -> 305920.5 | W15: ='Table 1. Total'!AC15 -> 361300.3 | X15: ='Table 1. Total'!AG15 -> 408061.1 | Y15: ='Table 1. Total'!AK15 -> 459960.7 | Z15: ='Table 1. Total'!AO15 -> 503735 | AA15: ='Table 1. Total'!AS15 -> 567910.7 | AB15: ='Table 1. Total'!AW15 -> 629971.2 | AC15: ='Table 1. Total'!BA15 -> 656429.4 | AD15: ='Table 1. Total'!BE15 -> 659289.6 | AE15: ='Table 1. Total'!BI15 -> 696487.2 | AF15: ='Table 1. Total'!BM15 -> 756759.7 | AG15: ='Table 1. Total'!BQ15 -> 866222.8 | AH15: ='Table 1. Total'!BU15 -> 945734.6 | AI15: ='Table 1. Total'!BY15 -> 963399.8 | AJ15: ='Table 1. Total'!CC15 -> 1056770.1
A16: Netherlands | B16: 176.7 | C16: 185.9 | D16: 196.6 | E16: 216.1 | F16: 228.8 | G16: 235.5 | H16: 251.9 | I16: 248.2 | J16: 240.3 | K16: 247.5 | L16: 246.2 | M16: 236.233 | N16: 239.037 | O16: 245.253 | P16: 256.822 | Q16: ='Table 1. Total'!E16 -> 266.661 | R16: ='Table 1. Total'!I16 -> 274.598 | S16: ='Table 1. Total'!M16 -> 264.472 | T16: ='Table 1. Total'!Q16 -> 266.545 | U16: ='Table 1. Total'!U16 -> 353.866 | V16: ='Table 1. Total'!Y16 -> 355.057 | W16: ='Table 1. Total'!AC16 -> 379.043 | X16: ='Table 1. Total'!AG16 -> 401.579 | Y16: ='Table 1. Total'!AK16 -> 432.723 | Z16: ='Table 1. Total'!AO16 -> 447.221 | AA16: ='Table 1. Total'!AS16 -> 455.93 | AB16: ='Table 1. Total'!AW16 -> 446.049 | AC16: ='Table 1. Total'!BA16 -> 438.204 | AD16: ='Table 1. Total'!BE16 -> 420.09 | AE16: ='Table 1. Total'!BI16 -> 405.617 | AF16: ='Table 1. Total'!BM16 -> 394.948 | AG16: ='Table 1. Total'!BQ16 -> 435.565 | AH16: ='Table 1. Total'!BU16 -> 449.62 | AI16: ='Table 1. Total'!BY16 -> 480.465 | AJ16: ='Table 1. Total'!CC16 -> 481.468
A17: New Zealand | B17: 22.644 | C17: 22.481 | D17: 24.324 | E17: 26.28 | F17: 28.672 | G17: 30.355 | H17: 31.322 | I17: 32.067 | J17: 30.825 | K17: 32.279 | L17: 33.07 | M17: 33.437 | N17: 34.408 | O17: 35.961 | P17: 37.472 | Q17: ='Table 1. Total'!E17 -> 35.442 | R17: ='Table 1. Total'!I17 -> 35.192 | S17: ='Table 1. Total'!M17 -> 29.599 | T17: ='Table 1. Total'!Q17 -> 31.035 | U17: ='Table 1. Total'!U17 -> 32.004 | V17: ='Table 1. Total'!Y17 -> 43.218 | W17: ='Table 1. Total'!AC17 -> 52.327 | X17: ='Table 1. Total'!AG17 -> 70.758 | Y17: ='Table 1. Total'!AK17 -> 79.069 | Z17: ='Table 1. Total'!AO17 -> 78.522 | AA17: ='Table 1. Total'!AS17 -> 82.347 | AB17: ='Table 1. Total'!AW17 -> 82.041 | AC17: ='Table 1. Total'!BA17 -> 84.199 | AD17: ='Table 1. Total'!BE17 -> 81.886 | AE17: ='Table 1. Total'!BI17 -> 89.994 | AF17: ='Table 1. Total'!BM17 -> 88.575 | AG17: ='Table 1. Total'!BQ17 -> 145.195 | AH17: ='Table 1. Total'!BU17 -> 165.956 | AI17: ='Table 1. Total'!BY17 -> 179.674 | AJ17: ='Table 1. Total'!CC17 -> 192.36
A18: Norway | B18: 229.16 | C18: 217.042 | D18: 310.044 | E18: 365.853 | F18: 458.937 | G18: 454.394 | H18: 315.311 | I18: 300.011 | J18: 293.974 | K18: 274.325 | L18: 316.103 | M18: 430.505 | N18: 424.568 | O18: 527.258 | P18: 677.804 | Q18: ='Table 1. Total'!E18 -> 768.099 | R18: ='Table 1. Total'!I18 -> 830.362 | S18: ='Table 1. Total'!M18 -> 1161.579 | T18: ='Table 1. Total'!Q18 -> 1164.455 | U18: ='Table 1. Total'!U18 -> 1233.543 | V18: ='Table 1. Total'!Y18 -> 1027.885 | W18: ='Table 1. Total'!AC18 -> 1108.379 | X18: ='Table 1. Total'!AG18 -> 810.594 | Y18: ='Table 1. Total'!AK18 -> 892.884 | Z18: ='Table 1. Total'!AO18 -> 948.621 | AA18: ='Table 1. Total'!AS18 -> 899.989 | AB18: ='Table 1. Total'!AW18 -> 1038.987 | AC18: ='Table 1. Total'!BA18 -> 1152.857 | AD18: ='Table 1. Total'!BE18 -> 1246.467 | AE18: ='Table 1. Total'!BI18 -> 1389.998 | AF18: ='Table 1. Total'!BM18 -> 1434.891 | AG18: ='Table 1. Total'!BQ18 -> 1563.851 | AH18: ='Table 1. Total'!BU18 -> 1787.432 | AI18: ='Table 1. Total'!BY18 -> 2083.819 | AJ18: ='Table 1. Total'!CC18 -> 2271.031
A19: Portugal | B19: 29.1 | C19: 34.6 | D19: 42.1 | E19: 43.1 | F19: 44.4 | G19: 50.8 | H19: 56.5 | I19: 61.1 | J19: 59.6 | K19: 61.9 | L19: 66.3 | M19: 69.592 | N19: 77.908 | O19: 85.527 | P19: 93.321 | Q19: ='Table 1. Total'!E19 -> 102.155 | R19: ='Table 1. Total'!I19 -> 114.543 | S19: ='Table 1. Total'!M19 -> 122.467 | T19: ='Table 1. Total'!Q19 -> 127.571 | U19: ='Table 1. Total'!U19 -> 135.209 | V19: ='Table 1. Total'!Y19 -> 153.624 | W19: ='Table 1. Total'!AC19 -> 179.653 | X19: ='Table 1. Total'!AG19 -> 201.044 | Y19: ='Table 1. Total'!AK19 -> 216.747 | Z19: ='Table 1. Total'!AO19 -> 223.313 | AA19: ='Table 1. Total'!AS19 -> 229.391 | AB19: ='Table 1. Total'!AW19 -> 235.046 | AC19: ='Table 1. Total'!BA19 -> 244.495 | AD19: ='Table 1. Total'!BE19 -> 246.399 | AE19: ='Table 1. Total'!BI19 -> 248.277 | AF19: ='Table 1. Total'!BM19 -> 249.044 | AG19: ='Table 1. Total'!BQ19 -> 269.578 | AH19: ='Table 1. Total'!BU19 -> 268.189 | AI19: ='Table 1. Total'!BY19 -> 271.358 | AJ19: ='Table 1. Total'!CC19 -> 261.849
A20: Slovenia | B20: … | C20: … | D20: … | E20: … | F20: … | G20: … | H20: 2.788 | I20: 3.54 | J20: 3.915 | K20: 4.429 | L20: 4.921 | M20: 5.484 | N20: 6.036 | O20: 6.708 | P20: 6.944 | Q20: ='Table 1. Total'!E20 -> 7.428 | R20: ='Table 1. Total'!I20 -> 7.69 | S20: ='Table 1. Total'!M20 -> 8.202 | T20: ='Table 1. Total'!Q20 -> 8.016 | U20: ='Table 1. Total'!U20 -> 8.263 | V20: ='Table 1. Total'!Y20 -> 12.519 | W20: ='Table 1. Total'!AC20 -> 13.918 | X20: ='Table 1. Total'!AG20 -> 17.22 | Y20: ='Table 1. Total'!AK20 -> 19.431 | Z20: ='Table 1. Total'!AO20 -> 25.53 | AA20: ='Table 1. Total'!AS20 -> 30.239 | AB20: ='Table 1. Total'!AW20 -> 32.111 | AC20: ='Table 1. Total'!BA20 -> 31.783 | AD20: ='Table 1. Total'!BE20 -> 31.922 | AE20: ='Table 1. Total'!BI20 -> 32.281 | AF20: ='Table 1. Total'!BM20 -> 31.793 | AG20: ='Table 1. Total'!BQ20 -> 37.47 | AH20: ='Table 1. Total'!BU20 -> 38.93 | AI20: ='Table 1. Total'!BY20 -> 41.395 | AJ20: ='Table 1. Total'!CC20 -> 43.739
A21: Spain | B21: 148.8 | C21: 173.6 | D21: 195.2 | E21: 207.7 | F21: 233.7 | G21: 255.1 | H21: 295.6 | I21: 324.3 | J21: 331.6 | K21: 346.4 | L21: 362.2 | M21: 374.557 | N21: 378.883 | O21: 384.145 | P21: 382.775 | Q21: ='Table 1. Total'!E21 -> 389.888 | R21: ='Table 1. Total'!I21 -> 393.479 | S21: ='Table 1. Total'!M21 -> 392.132 | T21: ='Table 1. Total'!Q21 -> 384.662 | U21: ='Table 1. Total'!U21 -> 440.621 | V21: ='Table 1. Total'!Y21 -> 569.535 | W21: ='Table 1. Total'!AC21 -> 649.153 | X21: ='Table 1. Total'!AG21 -> 743.043 | Y21: ='Table 1. Total'!AK21 -> 927.813 | Z21: ='Table 1. Total'!AO21 -> 1025.805 | AA21: ='Table 1. Total'!AS21 -> 1085.165 | AB21: ='Table 1. Total'!AW21 -> 1114.129 | AC21: ='Table 1. Total'!BA21 -> 1145.655 | AD21: ='Table 1. Total'!BE21 -> 1184.148 | AE21: ='Table 1. Total'!BI21 -> 1209.742 | AF21: ='Table 1. Total'!BM21 -> 1224.364 | AG21: ='Table 1. Total'!BQ21 -> 1346.916 | AH21: ='Table 1. Total'!BU21 -> 1429.404 | AI21: ='Table 1. Total'!BY21 -> 1504.105 | AJ21: ='Table 1. Total'!CC21 -> 1575.374
A22: Sweden | B22: 561.3 | C22: 593.3 | D22: 763.4 | E22: 962.4 | F22: 1094.2 | G22: 1208.8 | H22: 1310 | I22: 1357.071 | J22: 1370.729 | K22: 1424.195 | L22: 1376.76 | M22: 1214.95 | N22: 1302.144 | O22: 1297.554 | P22: 1335.709 | Q22: ='Table 1. Total'!E22 -> 1375.293 | R22: ='Table 1. Total'!I22 -> 1431.293 | S22: ='Table 1. Total'!M22 -> 1366.719 | T22: ='Table 1. Total'!Q22 -> 1298.322 | U22: ='Table 1. Total'!U22 -> 1287.298 | V22: ='Table 1. Total'!Y22 -> 1369.295 | W22: ='Table 1. Total'!AC22 -> 1370.64 | X22: ='Table 1. Total'!AG22 -> 1395.605 | Y22: ='Table 1. Total'!AK22 -> 1415.032 | Z22: ='Table 1. Total'!AO22 -> 1551.553 | AA22: ='Table 1. Total'!AS22 -> 1810.859 | AB22: ='Table 1. Total'!AW22 -> 1881.274 | AC22: ='Table 1. Total'!BA22 -> 1883.772 | AD22: ='Table 1. Total'!BE22 -> 1904.584 | AE22: ='Table 1. Total'!BI22 -> 1907.798 | AF22: ='Table 1. Total'!BM22 -> 1796.655 | AG22: ='Table 1. Total'!BQ22 -> 2015.37 | AH22: ='Table 1. Total'!BU22 -> 2004.815 | AI22: ='Table 1. Total'!BY22 -> 1972.413 | AJ22: ='Table 1. Total'!CC22 -> 1954.397
A23: Switzerland | B23: 83.924 | C23: 95.947 | D23: 107.97 | E23: 127.546 | F23: 148.355 | G23: 161.016 | H23: 171.837 | I23: 180.653 | J23: 192.965 | K23: 207.645 | L23: 200.179 | M23: 205.838 | N23: 205.43 | O23: 221.778 | P23: 226.28 | Q23: ='Table 1. Total'!E23 -> 229.685 | R23: ='Table 1. Total'!I23 -> 226.061 | S23: ='Table 1. Total'!M23 -> 211.955 | T23: ='Table 1. Total'!Q23 -> 201.843 | U23: ='Table 1. Total'!U23 -> 197.241 | V23: ='Table 1. Total'!Y23 -> 184.879 | W23: ='Table 1. Total'!AC23 -> 182.414 | X23: ='Table 1. Total'!AG23 -> 181.288 | Y23: ='Table 1. Total'!AK23 -> 188.025 | Z23: ='Table 1. Total'!AO23 -> 190.767 | AA23: ='Table 1. Total'!AS23 -> 195.129 | AB23: ='Table 1. Total'!AW23 -> 192.448 | AC23: ='Table 1. Total'!BA23 -> 187.807 | AD23: ='Table 1. Total'!BE23 -> 192.077 | AE23: ='Table 1. Total'!BI23 -> 185.45 | AF23: ='Table 1. Total'!BM23 -> 186.712 | AG23: ='Table 1. Total'!BQ23 -> 197.457 | AH23: ='Table 1. Total'!BU23 -> 200.354 | AI23: ='Table 1. Total'!BY23 -> 193.208 | AJ23: ='Table 1. Total'!CC23 -> 200.103
A24: United Kingdom | B24: 193.217 | C24: 189.581 | D24: 202.744 | E24: 248.331 | F24: 324.232 | G24: 330.02 | H24: 383.823 | I24: 407.117 | J24: 420.757 | K24: 419.066 | L24: 421.574 | M24: 414.826 | N24: 400.663 | O24: 422.18 | P24: 462.61 | Q24: ='Table 1. Total'!E24 -> 526.43 | R24: ='Table 1. Total'!I24 -> 573.493 | S24: ='Table 1. Total'!M24 -> 619.114 | T24: ='Table 1. Total'!Q24 -> 666.88 | U24: ='Table 1. Total'!U24 -> 809.985 | V24: ='Table 1. Total'!Y24 -> 1005.405 | W24: ='Table 1. Total'!AC24 -> 1220.252 | X24: ='Table 1. Total'!AG24 -> 1353.765 | Y24: ='Table 1. Total'!AK24 -> 1447.791 | Z24: ='Table 1. Total'!AO24 -> 1519.787 | AA24: ='Table 1. Total'!AS24 -> 1622.144 | AB24: ='Table 1. Total'!AW24 -> 1683.922 | AC24: ='Table 1. Total'!BA24 -> 1749.166 | AD24: ='Table 1. Total'!BE24 -> 1805.987 | AE24: ='Table 1. Total'!BI24 -> 1858.41 | AF24: ='Table 1. Total'!BM24 -> 1913.514 | AG24: ='Table 1. Total'!BQ24 -> 2226.332 | AH24: ='Table 1. Total'!BU24 -> 2402.766 | AI24: ='Table 1. Total'!BY24 -> 2516.819 | AJ24: ='Table 1. Total'!CC24 -> 2720.877
A25: United States | B25: 3117.515 | C25: 3402.66 | D25: 3785.078 | E25: 4164.195 | F25: 4514.972 | G25: 4713.119 | H25: 4910.113 | I25: 5119.515 | J25: 5247.668 | K25: 5259.565 | L25: 5244.22 | M25: 4981.406 | N25: 5123.519 | O25: 5523.241 | P25: 6046.996 | Q25: ='Table 1. Total'!E25 -> 7341.928 | R25: ='Table 1. Total'!I25 -> 7709.545 | S25: ='Table 1. Total'!M25 -> 7981.395 | T25: ='Table 1. Total'!Q25 -> 8348.06 | U25: ='Table 1. Total'!U25 -> 9758.877 | V25: ='Table 1. Total'!Y25 -> 11397.29 | W25: ='Table 1. Total'!AC25 -> 13109.307 | X25: ='Table 1. Total'!AG25 -> 14243.031 | Y25: ='Table 1. Total'!AK25 -> 15409.728 | Z25: ='Table 1. Total'!AO25 -> 16205.501 | AA25: ='Table 1. Total'!AS25 -> 16902.619 | AB25: ='Table 1. Total'!AW25 -> 17634.537 | AC25: ='Table 1. Total'!BA25 -> 18445.034 | AD25: ='Table 1. Total'!BE25 -> 19024.482 | AE25: ='Table 1. Total'!BI25 -> 20264.329 | AF25: ='Table 1. Total'!BM25 -> 21357.612 | AG25: ='Table 1. Total'!BQ25 -> 25710.881 | AH25: ='Table 1. Total'!BU25 -> 27130.289 | AI25: ='Table 1. Total'!BY25 -> 28499.037 | AJ25: ='Table 1. Total'!CC25 -> 31022.747
A26: Cyprus | B26: … | C26: … | D26: … | E26: … | F26: … | G26: … | H26: 3.732 | I26: 4.045 | J26: 4.633 | K26: 5.141 | L26: 5.583 | M26: 6.103 | N26: 6.746 | O26: 7.431 | P26: 8.281 | Q26: 9.16 | R26: 9.698 | S26: 9.717 | T26: 9.593 | U26: 8.8 | V26: 10.616 | W26: 11.543 | X26: 13.728 | Y26: 16.3 | Z26: 19.394 | AA26: 19.706 | AB26: 20.025 | AC26: 20.33 | AD26: 19.597 | AE26: 21.965 | AF26: 21.598 | AG26: 25.417 | AH26: 24.776 | AI26: 23.813 | AJ26: 23.076
A27: Estonia | B27: … | C27: … | D27: … | E27: … | F27: … | G27: … | H27: 0.236 | I27: 0.277 | J27: 0.311 | K27: 0.302 | L27: 0.348 | M27: 0.316 | N27: 0.344 | O27: 0.443 | P27: 0.49 | Q27: 0.505 | R27: 0.537 | S27: 0.64 | T27: 0.641 | U27: 0.777 | V27: 1.127 | W27: 1.178 | X27: 1.272 | Y27: 2.016 | Z27: 2.191 | AA27: 2.355 | AB27: 2.267 | AC27: 2.272 | AD27: 2.294 | AE27: 2.249 | AF27: 2.576 | AG27: 5.32 | AH27: 5.794 | AI27: 6.965 | AJ27: 7.708
A28: Iceland | B28: 114.734 | C28: 134.542 | D28: 154.183 | E28: 185.639 | F28: 220.078 | G28: 245.071 | H28: 267.611 | I28: 274.447 | J28: 279.351 | K28: 265.216 | L28: 497.639 | M28: 537.821 | N28: 668.96 | O28: 701.761 | P28: 745.818 | Q28: 784.696 | R28: 731.653 | S28: 865.981 | T28: 948.735 | U28: 1754.257 | V28: 2094.358 | W28: 2238.058 | X28: 2438.817 | Y28: 2471.131 | Z28: 2402.796 | AA28: 2405.555 | AB28: 2248.986 | AC28: 2071.73 | AD28: 1895.401 | AE28: 1798.772 | AF28: 2013.2 | AG28: 2270.442 | AH28: 2451.637 | AI28: 2621.714 | AJ28: 2689.558
A29: Israel | B29: 138.963 | C29: 161.794 | D29: 185.568 | E29: 204.919 | F29: 237.246 | G29: 267.77 | H29: 296.736 | I29: 337.153 | J29: 372.243 | K29: 422.764 | L29: 435.781 | M29: 430.214 | N29: 460.884 | O29: 518.57 | P29: 537.446 | Q29: 553.962 | R29: 564.29 | S29: 549.757 | T29: 536.974 | U29: 557.486 | V29: 608.446 | W29: 618.53 | X29: 644.732 | Y29: 679.465 | Z29: 709.755 | AA29: 729.999 | AB29: 741.542 | AC29: 753.41 | AD29: 761.61 | AE29: 803.807 | AF29: 837.727 | AG29: 999.299 | AH29: 1059.78 | AI29: 1053.579 | AJ29: 1143.294
A30: Latvia | B30: … | C30: … | D30: … | E30: … | F30: … | G30: … | H30: 0.561 | I30: 0.626 | J30: 0.62 | K30: 0.575 | L30: 0.905 | M30: 1.011 | N30: 1.304 | O30: 1.252 | P30: 1.41 | Q30: 1.629 | R30: 1.639 | S30: 1.737 | T30: 1.935 | U30: 4.511 | V30: 6.957 | W30: 8.538 | X30: 8.949 | Y30: 9.364 | Z30: 9.172 | AA30: 9.818 | AB30: 9.089 | AC30: 10.224 | AD30: 10.493 | AE30: 10.784 | AF30: 11.209 | AG30: 12.87 | AH30: 14.81 | AI30: 16.039 | AJ30: 17.579
A31: Lithuania | B31: … | C31: … | D31: … | E31: … | F31: 0.507 | G31: 0.764 | H31: 0.895 | I31: 1.352 | J31: 1.802 | K31: 2.154 | L31: 2.886 | M31: 2.912 | N31: 3.185 | O31: 3.366 | P31: 3.395 | Q31: 3.405 | R31: 3.702 | S31: 4.152 | T31: 4.61 | U31: 4.762 | V31: 7.529 | W31: 10.154 | X31: 11.632 | Y31: 13.266 | Z31: 13.553 | AA31: 14.829 | AB31: 15.882 | AC31: 15.448 | AD31: 16.542 | AE31: 15.323 | AF31: 17.526 | AG31: 23.063 | AH31: 24.536 | AI31: 25.672 | AJ31: 27.558
A32: Luxembourg | B32: 0.72 | C32: 0.65 | D32: 0.63 | E32: 0.82 | F32: 1.12 | G32: 1.14 | H32: 1.61 | I32: 1.61 | J32: 1.63 | K32: 1.65 | L32: 1.66 | M32: 1.723 | N32: 1.82 | O32: 1.863 | P32: 1.95 | Q32: 2.207 | R32: 2.407 | S32: 2.804 | T32: 3.046 | U32: 5.852 | V32: 5.969 | W32: 8.095 | X32: 8.201 | Y32: 9.7 | Z32: 10.998 | AA32: 11.317 | AB32: 11.432 | AC32: 11.003 | AD32: 12.667 | AE32: 12.544 | AF32: 13.921 | AG32: 15.799 | AH32: 17.637 | AI32: 19.078 | AJ32: 20.262
A33: Malta | B33: … | C33: … | D33: … | E33: … | F33: … | G33: … | H33: 0.968 | I33: 1.177 | J33: 1.569 | K33: 1.79 | L33: 2.442 | M33: 2.654 | N33: 2.989 | O33: 2.927 | P33: 3.267 | Q33: 3.45 | R33: 3.606 | S33: 3.473 | T33: 3.585 | U33: 3.837 | V33: 4.153 | W33: 4.463 | X33: 4.848 | Y33: 4.907 | Z33: 5.28 | AA33: 5.436 | AB33: 5.627 | AC33: 5.774 | AD33: 5.711 | AE33: 5.669 | AF33: 5.728 | AG33: 6.983 | AH33: 8.273 | AI33: 9.011 | AJ33: 9.791
A34: San Marino | B34: … | C34: … | D34: … | E34: … | F34: … | G34: … | H34: … | I34: … | J34: … | K34: … | L34: … | M34: … | N34: … | O34: … | P34: … | Q34: 0.233 | R34: 0.208 | S34: 0.215 | T34: 0.202 | U34: 0.253 | V34: 0.297 | W34: 0.283 | X34: 0.217 | Y34: 0.215 | Z34: 0.293 | AA34: 0.265 | AB34: 0.247 | AC34: 0.285 | AD34: 0.768 | AE34: 0.802 | AF34: 0.829 | AG34: 0.969 | AH34: 1.276 | AI34: 1.299 | AJ34: 1.331
A35: Singapore | B35: 46.028 | C35: 51.426 | D35: 59.041 | E35: 67.253 | F35: 69.822 | G35: 75.344 | H35: 86.508 | I35: 94.831 | J35: 102.372 | K35: 115.183 | L35: 125.777 | M35: 134.37 | N35: 149 | O35: 156.751 | P35: 169.332 | Q35: 186.598 | R35: 200.006 | S35: 206.439 | T35: 234.093 | U35: 255.465 | V35: 291.502 | W35: 321.182 | X35: 354.023 | Y35: 384.998 | Z35: 390.407 | AA35: 387.251 | AB35: 421.302 | AC35: 463.166 | AD35: 502.022 | AE35: 546.7 | AF35: 641.094 | AG35: 704.721 | AH35: 777.958 | AI35: 1079.758 | AJ35: 1150.26
A36: Slovak Republic | B36: … | C36: … | D36: … | E36: … | F36: … | G36: … | H36: 3.309 | I36: 5.09 | J36: 6.324 | K36: 6.325 | L36: 9.581 | M36: 10.975 | N36: 12.406 | O36: 12.35 | P36: 13.16 | Q36: 15.02 | R36: 13.988 | S36: 15.544 | T36: 17.214 | U36: 19.63 | V36: 23.321 | W36: 27.94 | X36: 30.994 | Y36: 38.108 | Z36: 40.763 | AA36: 40.878 | AB36: 41.474 | AC36: 42.554 | AD36: 43.654 | AE36: 44.479 | AF36: 45.392 | AG36: 55.091 | AH36: 61.346 | AI36: 63.499 | AJ36: 68.898
A38: Foreign (Billion LC) | B38: =B1 -> 1989 | C38: =C1 -> 1990 | D38: =D1 -> 1991 | E38: =E1 -> 1992 | F38: =F1 -> 1993 | G38: =G1 -> 1994 | H38: =H1 -> 1995 | I38: =I1 -> 1996 | ... AJ38: =AJ1 -> 2023 | AL38: Foreign (% of Total Debt) | AM38: =B1 -> 1989 | AN38: =C1 -> 1990 | AO38: =D1 -> 1991 | AP38: =E1 -> 1992 | AQ38: =F1 -> 1993 | AR38: =G1 -> 1994 | AS38: =H1 -> 1995 | AT38: =I1 -> 1996 | ... BU38: =AJ1 -> 2023
A39: Australia | B39: … | C39: … | D39: … | E39: … | F39: … | G39: … | H39: … | I39: … | J39: … | K39: … | L39: … | M39: … | N39: … | O39: … | P39: 23.614 | Q39: ='Table 2. Foreign'!E2 -> 27.535 | R39: ='Table 2. Foreign'!I2 -> 31.699 | S39: ='Table 2. Foreign'!M2 -> 31.193 | T39: ='Table 2. Foreign'!Q2 -> 39.621 | U39: ='Table 2. Foreign'!U2 -> 38.261 | V39: ='Table 2. Foreign'!Y2 -> 71.158 | W39: ='Table 2. Foreign'!AC2 -> 123.528 | X39: ='Table 2. Foreign'!AG2 -> 167.797 | Y39: ='Table 2. Foreign'!AK2 -> 182.97 | Z39: ='Table 2. Foreign'!AO2 -> 205.116 | AA39: ='Table 2. Foreign'!AS2 -> 234.477 | AB39: ='Table 2. Foreign'!AW2 -> 255.694 | AC39: ='Table 2. Foreign'!BA2 -> 257.978 | AD39: ='Table 2. Foreign'!BE2 -> 290.687 | AE39: ='Table 2. Foreign'!BI2 -> 304.959 | AF39: ='Table 2. Foreign'!BM2 -> 321.615 | AG39: ='Table 2. Foreign'!BQ2 -> 418.498 | AH39: ='Table 2. Foreign'!BU2 -> 401.683 | AI39: ='Table 2. Foreign'!BY2 -> 429.769 | AJ39: ='Table 2. Foreign'!CC2 -> 440.803 | AL39: Australia | AM39: =IF(ISNUMBER(B39/B$2),B39/B$2,"…") -> … | AN39: =IF(ISNUMBER(C39/C$2),C39/C$2,"…") -> … | AO39: =IF(ISNUMBER(D39/D$2),D39/D$2,"…") -> … | AP39: =IF(ISNUMBER(E39/E$2),E39/E$2,"…") -> … | AQ39: =IF(ISNUMBER(F39/F$2),F39/F$2,"…") -> … | AR39: =IF(ISNUMBER(G39/G$2),G39/G$2,"…") -> … | AS39: =IF(ISNUMBER(H39/H$2),H39/H$2,"…") -> … | AT39: =IF(ISNUMBER(I39/I$2),I39/I$2,"…") -> … | ... BU39: =IF(ISNUMBER(AJ39/AJ$2),AJ39/AJ$2,"…") -> 0.33570616
A40: Austria | B40: … | C40: … | D40: … | E40: … | F40: … | G40: … | H40: 35.525 | I40: 35.533 | J40: 34.426 | K40: 46.972 | L40: 64.331 | M40: 73.696 | N40: 88.053 | O40: 97.675 | P40: 104.675 | Q40: ='Table 2. Foreign'!E3 -> 113.284 | R40: ='Table 2. Foreign'!I3 -> 125.263 | S40: ='Table 2. Foreign'!M3 -> 139.635 | T40: ='Table 2. Foreign'!Q3 -> 145.137 | U40: ='Table 2. Foreign'!U3 -> 159.52 | V40: ='Table 2. Foreign'!Y3 -> 175.875 | W40: ='Table 2. Foreign'!AC3 -> 185.271 | X40: ='Table 2. Foreign'!AG3 -> 192.996 | Y40: ='Table 2. Foreign'!AK3 -> 199.025 | Z40: ='Table 2. Foreign'!AO3 -> 200.46 | AA40: ='Table 2. Foreign'!AS3 -> 214.497 | AB40: ='Table 2. Foreign'!AW3 -> 216.167 | AC40: ='Table 2. Foreign'!BA3 -> 208.313 | AD40: ='Table 2. Foreign'!BE3 -> 194.681 | AE40: ='Table 2. Foreign'!BI3 -> 187.715 | AF40: ='Table 2. Foreign'!BM3 -> 187.452 | AG40: ='Table 2. Foreign'!BQ3 -> 202.618 | AH40: ='Table 2. Foreign'!BU3 -> 186.389 | AI40: ='Table 2. Foreign'!BY3 -> 200.901 | AJ40: ='Table 2. Foreign'!CC3 -> 222.671 | AL40: Austria | AM40: =IF(ISNUMBER(B40/B$3),B40/B$3,"…") -> … | AN40: =IF(ISNUMBER(C40/C$3),C40/C$3,"…") -> … | AO40: =IF(ISNUMBER(D40/D$3),D40/D$3,"…") -> … | AP40: =IF(ISNUMBER(E40/E$3),E40/E$3,"…") -> … | AQ40: =IF(ISNUMBER(F40/F$3),F40/F$3,"…") -> … | AR40: =IF(ISNUMBER(G40/G$3),G40/G$3,"…") -> … | AS40: =IF(ISNUMBER(H40/H$3),H40/H$3,"…") -> 0.28351955 | AT40: =IF(ISNUMBER(I40/I$3),I40/I$3,"…") -> 0.2838099 | ... BU40: =IF(ISNUMBER(AJ40/AJ$3),AJ40/AJ$3,"…") -> 0.59901434
A41: Belgium | B41: … | C41: … | D41: … | E41: … | F41: … | G41: … | H41: 65.311 | I41: 61.392 | J41: 64.776 | K41: 70.597 | L41: 85.642 | M41: 107.618 | N41: 121.962 | O41: 135.723 | P41: 140.721 | Q41: ='Table 2. Foreign'!E4 -> 144.483 | R41: ='Table 2. Foreign'!I4 -> 150.757 | S41: ='Table 2. Foreign'!M4 -> 154.655 | T41: ='Table 2. Foreign'!Q4 -> 171.689 | U41: ='Table 2. Foreign'!U4 -> 191.069 | V41: ='Table 2. Foreign'!Y4 -> 193.349 | W41: ='Table 2. Foreign'!AC4 -> 196.752 | X41: ='Table 2. Foreign'!AG4 -> 180.429 | Y41: ='Table 2. Foreign'!AK4 -> 187.177 | Z41: ='Table 2. Foreign'!AO4 -> 203.771 | AA41: ='Table 2. Foreign'!AS4 -> 234.219 | AB41: ='Table 2. Foreign'!AW4 -> 234.354 | AC41: ='Table 2. Foreign'!BA4 -> 242.333 | AD41: ='Table 2. Foreign'!BE4 -> 235.301 | AE41: ='Table 2. Foreign'!BI4 -> 244.141 | AF41: ='Table 2. Foreign'!BM4 -> 261.031 | AG41: ='Table 2. Foreign'!BQ4 -> 283.314 | AH41: ='Table 2. Foreign'!BU4 -> 284.152 | AI41: ='Table 2. Foreign'!BY4 -> 308.9 | AJ41: ='Table 2. Foreign'!CC4 -> 326.362 | AL41: Belgium | AM41: =IF(ISNUMBER(B41/B$4),B41/B$4,"…") -> … | AN41: =IF(ISNUMBER(C41/C$4),C41/C$4,"…") -> … | AO41: =IF(ISNUMBER(D41/D$4),D41/D$4,"…") -> … | AP41: =IF(ISNUMBER(E41/E$4),E41/E$4,"…") -> … | AQ41: =IF(ISNUMBER(F41/F$4),F41/F$4,"…") -> … | AR41: =IF(ISNUMBER(G41/G$4),G41/G$4,"…") -> … | AS41: =IF(ISNUMBER(H41/H$4),H41/H$4,"…") -> 0.22669559 | AT41: =IF(ISNUMBER(I41/I$4),I41/I$4,"…") -> 0.22075512 | ... BU41: =IF(ISNUMBER(AJ41/AJ$4),AJ41/AJ$4,"…") -> 0.53067768
...

Sheet ExtendedDataset_Currency
A1: Total debt securities in local currency (in percent of total debt securities) | B1: 1989 | C1: =B1+1 -> 1990 | D1: =C1+1 -> 1991 | E1: =D1+1 -> 1992 | F1: =E1+1 -> 1993 | G1: =F1+1 -> 1994 | H1: =G1+1 -> 1995 | I1: =H1+1 -> 1996 | J1: =I1+1 -> 1997 | ... AJ1: =AI1+1 -> 2023
A2: Australia | B2: … | C2: … | D2: … | E2: … | F2: … | G2: 0.939 | H2: 0.939 | I2: 0.942 | J2: 0.939 | K2: 0.935 | L2: 0.965 | M2: 0.968 | N2: 0.979 | O2: 0.974 | P2: 0.972 | Q2: 0.974 | R2: 0.978 | S2: 0.985 | T2: 0.989 | U2: 0.985 | V2: 0.989 | W2: 0.993 | X2: 0.995 | Y2: 0.996 | Z2: 0.997 | AA2: 0.998 | AB2: 0.998 | AC2: 0.999 | AD2: 0.999 | AE2: 0.999 | AF2: 0.999 | AG2: 0.999 | AH2: 0.999 | AI2: 0.999 | AJ2: 0.999
A3: Austria | B3: 0.882 | C3: 0.878 | D3: 0.879 | E3: 0.888 | F3: 0.883 | G3: 0.865 | H3: 0.867 | I3: 0.864 | J3: 0.868 | K3: 0.842 | L3: 0.845 | M3: 0.868 | N3: 0.869 | O3: 0.865 | P3: 0.866 | Q3: 0.866 | R3: 0.858 | S3: 0.89 | T3: 0.908 | U3: 0.88 | V3: 0.905 | W3: 0.922 | X3: 0.928 | Y3: 0.937 | Z3: 0.959 | AA3: 0.957 | AB3: 0.957 | AC3: 0.958 | AD3: 0.972 | AE3: 0.976 | AF3: 0.971 | AG3: 0.95 | AH3: 0.969 | AI3: 0.967 | AJ3: 0.973
A4: Belgium | B4: 0.951 | C4: 0.947 | D4: 0.951 | E4: 0.961 | F4: 0.947 | G4: 0.949 | H4: 0.951 | I4: 0.955 | J4: 0.951 | K4: 0.961 | L4: 0.96 | M4: 0.964 | N4: 0.968 | O4: 0.975 | P4: 0.985 | Q4: 0.989 | R4: 0.988 | S4: 0.99 | T4: 0.993 | U4: 0.966 | V4: 0.984 | W4: 0.978 | X4: 0.962 | Y4: 0.984 | Z4: 0.984 | AA4: 0.985 | AB4: 0.985 | AC4: 0.978 | AD4: 0.974 | AE4: 0.985 | AF4: 0.992 | AG4: 0.989 | AH4: 0.993 | AI4: 0.991 | AJ4: 0.994
A5: Canada | B5: 0.85 | C5: 0.841 | D5: 0.849 | E5: 0.835 | F5: 0.819 | G5: 0.789 | H5: 0.789 | I5: 0.79 | J5: 0.799 | K5: 0.768 | L5: 0.791 | M5: 0.808 | N5: 0.801 | O5: 0.802 | P5: 0.833 | Q5: 0.849 | R5: 0.856 | S5: 0.855 | T5: 0.877 | U5: 0.865 | V5: 0.877 | W5: 0.876 | X5: 0.877 | Y5: 0.881 | Z5: 0.883 | AA5: 0.877 | AB5: 0.873 | AC5: 0.887 | AD5: 0.885 | AE5: 0.879 | AF5: 0.888 | AG5: 0.897 | AH5: 0.902 | AI5: 0.908 | AJ5: 0.907
A6: Czech Republic | B6: … | C6: … | D6: … | E6: … | F6: … | G6: … | H6: … | I6: … | J6: … | K6: … | L6: … | M6: … | N6: … | O6: … | P6: … | Q6: … | R6: … | S6: 0.871 | T6: 0.89 | U6: 0.837 | V6: 0.813 | W6: 0.797 | X6: 0.806 | Y6: 0.785 | Z6: 0.781 | AA6: 0.836 | AB6: 0.848 | AC6: 0.858 | AD6: 0.864 | AE6: 0.897 | AF6: 0.885 | AG6: 0.913 | AH6: 0.96 | AI6: 0.982 | AJ6: 0.986
A7: Denmark | B7: … | C7: … | D7: … | E7: … | F7: … | G7: … | H7: … | I7: … | J7: … | K7: … | L7: 1 | M7: 1 | N7: 1 | O7: 0.927 | P7: 0.955 | Q7: 0.971 | R7: 0.975 | S7: 0.985 | T7: 0.989 | U7: 0.955 | V7: 0.847 | W7: 0.854 | X7: 0.87 | Y7: 0.904 | Z7: 0.915 | AA7: 0.939 | AB7: 0.957 | AC7: 0.985 | AD7: 0.998 | AE7: 0.999 | AF7: 0.999 | AG7: 0.984 | AH7: 0.982 | AI7: 0.98 | AJ7: 0.963
A8: Finland | B8: 0.701 | C8: 0.72 | D8: 0.724 | E8: 0.658 | F8: 0.635 | G8: 0.678 | H8: 0.748 | I8: 0.77 | J8: 0.797 | K8: 0.848 | L8: 0.83 | M8: 0.855 | N8: 0.856 | O8: 0.855 | P8: 0.907 | Q8: 0.922 | R8: 0.906 | S8: 0.913 | T8: 0.942 | U8: 0.93 | V8: 0.944 | W8: 0.87 | X8: 0.896 | Y8: 0.853 | Z8: 0.847 | AA8: 0.826 | AB8: 0.825 | AC8: 0.857 | AD8: 0.849 | AE8: 0.899 | AF8: 0.941 | AG8: 0.965 | AH8: 0.977 | AI8: 0.961 | AJ8: 0.979
A9: France | B9: 1 | C9: 1 | D9: 1 | E9: 0.999 | F9: 0.999 | G9: 0.998 | H9: 0.998 | I9: 0.983 | J9: 0.976 | K9: 0.984 | L9: 0.988 | M9: 0.987 | N9: 0.993 | O9: 0.996 | P9: 0.997 | Q9: 0.984 | R9: 0.978 | S9: 0.981 | T9: 0.983 | U9: 0.979 | V9: 0.969 | W9: 0.967 | X9: 0.961 | Y9: 0.968 | Z9: 0.97 | AA9: 0.972 | AB9: 0.969 | AC9: 0.961 | AD9: 0.963 | AE9: 0.975 | AF9: 0.976 | AG9: 0.963 | AH9: 0.962 | AI9: 0.972 | AJ9: 0.972
A10: Germany | B10: 1 | C10: 1 | D10: 1 | E10: 1 | F10: 1 | G10: 1 | H10: 1 | I10: 1 | J10: 1 | K10: 1 | L10: 1 | M10: 1 | N10: 0.999 | O10: 0.998 | P10: 0.995 | Q10: 0.994 | R10: 0.989 | S10: 0.99 | T10: 0.991 | U10: 0.99 | V10: 0.987 | W10: 0.992 | X10: 0.977 | Y10: 0.963 | Z10: 0.964 | AA10: 0.959 | AB10: 0.949 | AC10: 0.945 | AD10: 0.942 | AE10: 0.949 | AF10: 0.955 | AG10: 0.959 | AH10: 0.97 | AI10: 0.981 | AJ10: 0.989
A11: Greece | B11: … | C11: … | D11: … | E11: … | F11: … | G11: … | H11: 1 | I11: 1 | J11: 1 | K11: 1 | L11: 1 | M11: 1 | N11: 1 | O11: 1 | P11: 1 | Q11: 1 | R11: 1 | S11: 1 | T11: 1 | U11: 0.981 | V11: 0.986 | W11: 0.985 | X11: 0.985 | Y11: 0.974 | Z11: 0.988 | AA11: 0.987 | AB11: 0.986 | AC11: 0.992 | AD11: 1 | AE11: 1 | AF11: 1 | AG11: 1 | AH11: 1 | AI11: 1 | AJ11: 1
A12: Ireland | B12: 1 | C12: 1 | D12: 1 | E12: 1 | F12: 1 | G12: 1 | H12: 1 | I12: 1 | J12: 1 | K12: 1 | L12: 1 | M12: 1 | N12: 1 | O12: 1 | P12: 1 | Q12: 1 | R12: 1 | S12: 1 | T12: 1 | U12: 1 | V12: 0.954 | W12: 0.992 | X12: 0.998 | Y12: 0.997 | Z12: 0.999 | AA12: 0.98 | AB12: 0.993 | AC12: 0.997 | AD12: 0.997 | AE12: 0.996 | AF12: 1 | AG12: 0.985 | AH12: 0.988 | AI12: 1 | AJ12: 1
A13: Italy | B13: 0.988 | C13: 0.989 | D13: 0.989 | E13: 0.989 | F13: 0.979 | G13: 0.975 | H13: 0.972 | I13: 0.968 | J13: 0.965 | K13: 0.965 | L13: 0.961 | M13: 0.952 | N13: 0.95 | O13: 0.95 | P13: 0.951 | Q13: 0.952 | R13: 0.948 | S13: 0.961 | T13: 0.967 | U13: 0.972 | V13: 0.975 | W13: 0.973 | X13: 0.976 | Y13: 0.981 | Z13: 0.985 | AA13: 0.985 | AB13: 0.99 | AC13: 0.993 | AD13: 0.995 | AE13: 0.996 | AF13: 0.993 | AG13: 0.993 | AH13: 0.991 | AI13: 0.991 | AJ13: 0.993
A14: Japan | B14: … | C14: … | D14: … | E14: … | F14: … | G14: … | H14: … | I14: … | J14: … | K14: … | L14: … | M14: … | N14: … | O14: … | P14: … | Q14: … | R14: … | S14: … | T14: … | U14: … | V14: … | W14: … | X14: … | Y14: 1 | Z14: 1 | AA14: 0.999 | AB14: 0.999 | AC14: 0.999 | AD14: 0.999 | AE14: 0.999 | AF14: 0.999 | AG14: 0.999 | AH14: 0.999 | AI14: 0.999 | AJ14: 0.999
A15: Korea | B15: … | C15: … | D15: … | E15: … | F15: … | G15: … | H15: … | I15: … | J15: … | K15: … | L15: … | M15: … | N15: … | O15: 0.955 | P15: 0.966 | Q15: 0.975 | R15: 0.978 | S15: 0.98 | T15: 0.982 | U15: 0.986 | V15: 0.981 | W15: 0.984 | X15: 0.985 | Y15: 0.987 | Z15: 0.988 | AA15: 0.99 | AB15: 0.99 | AC15: 0.991 | AD15: 0.99 | AE15: 0.989 | AF15: 0.99 | AG15: 0.99 | AH15: 0.988 | AI15: 0.988 | AJ15: 0.989
A16: Netherlands | B16: 1 | C16: 1 | D16: 1 | E16: 1 | F16: 1 | G16: 1 | H16: 1 | I16: 1 | J16: 1 | K16: 1 | L16: 1 | M16: 1 | N16: 1 | O16: 1 | P16: 1 | Q16: 1 | R16: 1 | S16: 1 | T16: 1 | U16: 0.957 | V16: 0.981 | W16: 0.982 | X16: 0.976 | Y16: 0.943 | Z16: 0.978 | AA16: 0.979 | AB16: 0.985 | AC16: 0.984 | AD16: 0.997 | AE16: 0.991 | AF16: 0.997 | AG16: 0.999 | AH16: 0.999 | AI16: 0.967 | AJ16: 0.987
A17: New Zealand | B17: … | C17: … | D17: … | E17: … | F17: … | G17: … | H17: … | I17: … | J17: … | K17: … | L17: … | M17: … | N17: … | O17: … | P17: … | Q17: … | R17: … | S17: … | T17: … | U17: … | V17: … | W17: … | X17: … | Y17: … | Z17: … | AA17: … | AB17: … | AC17: … | AD17: … | AE17: … | AF17: … | AG17: … | AH17: … | AI17: … | AJ17: …
A18: Norway | B18: … | C18: … | D18: … | E18: … | F18: … | G18: … | H18: … | I18: … | J18: … | K18: … | L18: … | M18: … | N18: … | O18: … | P18: … | Q18: … | R18: 1 | S18: 1 | T18: 1 | U18: 1 | V18: 1 | W18: 1 | X18: 1 | Y18: 1 | Z18: 1 | AA18: 1 | AB18: 1 | AC18: 1 | AD18: 1 | AE18: 1 | AF18: 1 | AG18: 1 | AH18: 1 | AI18: 1 | AJ18: 1
A19: Portugal | B19: 0.991 | C19: 0.992 | D19: 0.993 | E19: 0.994 | F19: 0.951 | G19: 0.955 | H19: 0.944 | I19: 0.946 | J19: 0.931 | K19: 0.935 | L19: 0.906 | M19: 0.923 | N19: 0.91 | O19: 0.954 | P19: 0.979 | Q19: 0.992 | R19: 0.993 | S19: 0.995 | T19: 0.997 | U19: 0.991 | V19: 0.983 | W19: 0.984 | X19: 0.984 | Y19: 0.987 | Z19: 0.988 | AA19: 0.962 | AB19: 0.968 | AC19: 0.97 | AD19: 0.975 | AE19: 0.975 | AF19: 0.974 | AG19: 0.978 | AH19: 0.983 | AI19: 0.984 | AJ19: 0.986
A20: Slovenia | B20: … | C20: … | D20: … | E20: … | F20: … | G20: … | H20: … | I20: … | J20: … | K20: 0.895 | L20: 0.893 | M20: 0.896 | N20: 0.989 | O20: 0.994 | P20: 0.996 | Q20: 0.998 | R20: 0.999 | S20: 1 | T20: 1 | U20: 1 | V20: 1 | W20: 1 | X20: 1 | Y20: 0.899 | Z20: 0.817 | AA20: 0.72 | AB20: 0.707 | AC20: 0.776 | AD20: 0.863 | AE20: 0.904 | AF20: 0.947 | AG20: 0.96 | AH20: 0.959 | AI20: 0.98 | AJ20: 0.965
A21: Spain | B21: 0.985 | C21: 0.983 | D21: 0.984 | E21: 0.964 | F21: 0.966 | G21: 0.967 | H21: 0.967 | I21: 0.969 | J21: 0.967 | K21: 0.964 | L21: 0.958 | M21: 0.957 | N21: 0.955 | O21: 0.965 | P21: 0.97 | Q21: 0.976 | R21: 0.98 | S21: 0.983 | T21: 0.985 | U21: 0.981 | V21: 0.981 | W21: 0.984 | X21: 0.988 | Y21: 0.994 | Z21: 0.995 | AA21: 0.996 | AB21: 0.996 | AC21: 0.996 | AD21: 0.997 | AE21: 0.999 | AF21: 0.999 | AG21: 0.999 | AH21: 0.999 | AI21: 0.999 | AJ21: 0.999
A22: Sweden | B22: … | C22: … | D22: … | E22: … | F22: … | G22: … | H22: … | I22: … | J22: … | K22: 0.707 | L22: 0.75 | M22: 0.771 | N22: 0.772 | O22: 0.795 | P22: 0.851 | Q22: 0.864 | R22: 0.868 | S22: 0.876 | T22: 0.876 | U22: 0.9 | V22: 0.827 | W22: 0.837 | X22: 0.871 | Y22: 0.87 | Z22: 0.798 | AA22: 0.768 | AB22: 0.74 | AC22: 0.735 | AD22: 0.749 | AE22: 0.757 | AF22: 0.786 | AG22: 0.81 | AH22: 0.847 | AI22: 0.864 | AJ22: 0.964
A23: Switzerland | B23: … | C23: … | D23: … | E23: … | F23: … | G23: … | H23: … | I23: … | J23: … | K23: … | L23: 1 | M23: 1 | N23: 1 | O23: 1 | P23: 1 | Q23: 1 | R23: 1 | S23: 1 | T23: 1 | U23: 1 | V23: 1 | W23: 1 | X23: 1 | Y23: 1 | Z23: 1 | AA23: 1 | AB23: 1 | AC23: 1 | AD23: 1 | AE23: 1 | AF23: 1 | AG23: 1 | AH23: 1 | AI23: 1 | AJ23: 1
A24: United Kingdom | B24: … | C24: … | D24: … | E24: … | F24: … | G24: … | H24: … | I24: … | J24: … | K24: 1 | L24: 1 | M24: 1 | N24: 1 | O24: 1 | P24: 1 | Q24: 1 | R24: 1 | S24: 1 | T24: 1 | U24: 1 | V24: 1 | W24: 1 | X24: 1 | Y24: 1 | Z24: 1 | AA24: 1 | AB24: 1 | AC24: 1 | AD24: 1 | AE24: 1 | AF24: 1 | AG24: 1 | AH24: 1 | AI24: 1 | AJ24: 1
A25: United States | B25: 1 | C25: 1 | D25: 1 | E25: 1 | F25: 1 | G25: 1 | H25: 1 | I25: 1 | J25: 1 | K25: 1 | L25: 1 | M25: 1 | N25: 1 | O25: 1 | P25: 1 | Q25: 1 | R25: 1 | S25: 1 | T25: 1 | U25: 1 | V25: 1 | W25: 1 | X25: 1 | Y25: 1 | Z25: 1 | AA25: 1 | AB25: 1 | AC25: 1 | AD25: 1 | AE25: 1 | AF25: 1 | AG25: 1 | AH25: 1 | AI25: 1 | AJ25: 1
A26: Cyprus | B26: … | C26: … | D26: … | E26: … | F26: … | G26: … | H26: … | I26: … | J26: … | K26: … | L26: … | M26: … | N26: … | O26: … | P26: … | Q26: 1 | R26: 1 | S26: 1 | T26: 1 | U26: 1 | V26: 1 | W26: 1 | X26: 0.995 | Y26: 1 | Z26: 1 | AA26: 1 | AB26: 1 | AC26: 1 | AD26: 1 | AE26: 1 | AF26: 1 | AG26: 1 | AH26: 1 | AI26: 1 | AJ26: 1
A27: Estonia | B27: … | C27: … | D27: … | E27: … | F27: … | G27: … | H27: … | I27: … | J27: … | K27: … | L27: … | M27: … | N27: … | O27: … | P27: … | Q27: … | R27: … | S27: … | T27: … | U27: 1 | V27: 1 | W27: 1 | X27: 0.934 | Y27: 0.932 | Z27: 0.951 | AA27: 0.947 | AB27: 0.951 | AC27: 0.964 | AD27: 0.973 | AE27: 0.985 | AF27: 0.993 | AG27: 1 | AH27: 1 | AI27: 1 | AJ27: 1
A28: Iceland | B28: … | C28: … | D28: … | E28: … | F28: … | G28: … | H28: … | I28: … | J28: … | K28: … | L28: … | M28: … | N28: … | O28: … | P28: … | Q28: … | R28: … | S28: … | T28: … | U28: … | V28: … | W28: … | X28: … | Y28: … | Z28: … | AA28: … | AB28: … | AC28: … | AD28: … | AE28: … | AF28: … | AG28: … | AH28: … | AI28: … | AJ28: …
A29: Israel | B29: … | C29: … | D29: … | E29: … | F29: … | G29: … | H29: 0.695 | I29: 0.688 | J29: 0.68 | K29: 0.619 | L29: 0.624 | M29: 0.643 | N29: 0.674 | O29: 0.68 | P29: 0.736 | Q29: 0.755 | R29: 0.748 | S29: 0.759 | T29: 0.775 | U29: 0.808 | V29: 0.827 | W29: 0.835 | X29: 0.833 | Y29: 0.847 | Z29: 0.857 | AA29: 0.847 | AB29: 0.86 | AC29: 0.868 | AD29: 0.863 | AE29: 0.841 | AF29: 0.855 | AG29: 0.813 | AH29: 0.836 | AI29: 0.804 | AJ29: 0.785
A30: Latvia | B30: … | C30: … | D30: … | E30: … | F30: … | G30: … | H30: … | I30: … | J30: … | K30: … | L30: … | M30: … | N30: … | O30: … | P30: … | Q30: … | R30: … | S30: … | T30: … | U30: … | V30: … | W30: … | X30: 0.824 | Y30: 0.462 | Z30: 0.471 | AA30: 0.605 | AB30: 0.704 | AC30: 0.746 | AD30: 0.883 | AE30: 0.887 | AF30: 0.897 | AG30: 0.969 | AH30: 1 | AI30: 1 | AJ30: 1
A31: Lithuania | B31: … | C31: … | D31: … | E31: … | F31: … | G31: … | H31: … | I31: … | J31: … | K31: … | L31: … | M31: … | N31: … | O31: … | P31: … | Q31: … | R31: … | S31: … | T31: … | U31: … | V31: … | W31: … | X31: … | Y31: 0.487 | Z31: 0.491 | AA31: 0.513 | AB31: 0.604 | AC31: 0.603 | AD31: 0.712 | AE31: 0.694 | AF31: 0.73 | AG31: 0.879 | AH31: 0.935 | AI31: 1 | AJ31: 1
A32: Luxembourg | B32: 1 | C32: 1 | D32: 1 | E32: 1 | F32: 1 | G32: 1 | H32: 1 | I32: 1 | J32: 1 | K32: 1 | L32: 1 | M32: 1 | N32: 1 | O32: 1 | P32: 1 | Q32: 1 | R32: 1 | S32: 1 | T32: … | U32: 1 | V32: 1 | W32: 1 | X32: 1 | Y32: 1 | Z32: 1 | AA32: 1 | AB32: 1 | AC32: 1 | AD32: 1 | AE32: 1 | AF32: 1 | AG32: 1 | AH32: 1 | AI32: 1 | AJ32: 1
A33: Malta | B33: … | C33: … | D33: … | E33: … | F33: … | G33: … | H33: … | I33: … | J33: … | K33: … | L33: … | M33: … | N33: … | O33: … | P33: … | Q33: 1 | R33: 1 | S33: 1 | T33: 1 | U33: 1 | V33: 1 | W33: 1 | X33: 1 | Y33: 1 | Z33: 1 | AA33: 1 | AB33: 1 | AC33: 1 | AD33: 1 | AE33: 1 | AF33: 1 | AG33: 1 | AH33: 1 | AI33: 1 | AJ33: 1
A34: San Marino | B34: … | C34: … | D34: … | E34: … | F34: … | G34: … | H34: … | I34: … | J34: … | K34: … | L34: … | M34: … | N34: … | O34: … | P34: … | Q34: … | R34: … | S34: … | T34: … | U34: … | V34: … | W34: … | X34: … | Y34: … | Z34: … | AA34: … | AB34: … | AC34: … | AD34: … | AE34: … | AF34: … | AG34: … | AH34: … | AI34: … | AJ34: …
A35: Singapore | B35: 1 | C35: 1 | D35: 1 | E35: 1 | F35: 1 | G35: 1 | H35: 1 | I35: 1 | J35: 1 | K35: 1 | L35: 1 | M35: 1 | N35: 1 | O35: 1 | P35: 1 | Q35: 1 | R35: 1 | S35: 1 | T35: 1 | U35: 1 | V35: 1 | W35: 1 | X35: 1 | Y35: 1 | Z35: 1 | AA35: 1 | AB35: 1 | AC35: 1 | AD35: 1 | AE35: 1 | AF35: 1 | AG35: 1 | AH35: 1 | AI35: 1 | AJ35: 1
A36: Slovak Republic | B36: … | C36: … | D36: … | E36: … | F36: 1 | G36: 1 | H36: 1 | I36: 1 | J36: 1 | K36: 0.907 | L36: 0.903 | M36: 0.913 | N36: 0.959 | O36: 0.966 | P36: 1 | Q36: 1 | R36: 1 | S36: 1 | T36: 1 | U36: 1 | V36: 1 | W36: 1 | X36: 1 | Y36: 0.938 | Z36: 0.924 | AA36: 0.91 | AB36: 0.917 | AC36: 0.922 | AD36: 0.931 | AE36: 0.939 | AF36: 0.948 | AG36: 0.96 | AH36: 0.961 | AI36: 0.991 | AJ36: 0.995
A38: Foreign holdings of local currency debt securities (in percent of all foreign holdings) | B38: 1989 | C38: =B38+1 -> 1990 | D38: =C38+1 -> 1991 | E38: =D38+1 -> 1992 | F38: =E38+1 -> 1993 | G38: =F38+1 -> 1994 | H38: =G38+1 -> 1995 | I38: =H38+1 -> 1996 | J38: =I38+1 -> 1997 | ... AJ38: =AI38+1 -> 2023
A39: Australia | B39: … | C39: … | D39: … | E39: … | F39: … | G39: 0.939 | H39: 0.939 | I39: 0.942 | J39: 0.939 | K39: 0.935 | L39: 0.965 | M39: 0.968 | N39: 0.979 | O39: 0.974 | P39: 0.972 | Q39: 0.974 | R39: 0.978 | S39: 0.985 | T39: 0.989 | U39: 0.985 | V39: 0.989 | W39: 0.993 | X39: 0.995 | Y39: 0.996 | Z39: 0.997 | AA39: 0.998 | AB39: 0.998 | AC39: 0.999 | AD39: 0.999 | AE39: 0.999 | AF39: 0.999 | AG39: 0.999 | AH39: 0.999 | AI39: 0.999 | AJ39: 0.999
A40: Austria | B40: 0.882 | C40: 0.878 | D40: 0.879 | E40: 0.888 | F40: 0.883 | G40: 0.865 | H40: 0.867 | I40: 0.864 | J40: 0.868 | K40: 0.842 | L40: 0.845 | M40: 0.868 | N40: 0.869 | O40: 0.865 | P40: 0.866 | Q40: 0.866 | R40: 0.858 | S40: 0.89 | T40: 0.908 | U40: 0.88 | V40: 0.905 | W40: 0.922 | X40: 0.928 | Y40: 0.937 | Z40: 0.959 | AA40: 0.957 | AB40: 0.957 | AC40: 0.958 | AD40: 0.972 | AE40: 0.976 | AF40: 0.971 | AG40: 0.95 | AH40: 0.969 | AI40: 0.967 | AJ40: 0.973
A41: Belgium | B41: 0.951 | C41: 0.947 | D41: 0.951 | E41: 0.961 | F41: 0.947 | G41: 0.949 | H41: 0.951 | I41: 0.955 | J41: 0.951 | K41: 0.961 | L41: 0.96 | M41: 0.964 | N41: 0.968 | O41: 0.975 | P41: 0.985 | Q41: 0.989 | R41: 0.988 | S41: 0.99 | T41: 0.993 | U41: 0.966 | V41: 0.984 | W41: 0.978 | X41: 0.962 | Y41: 0.984 | Z41: 0.984 | AA41: 0.985 | AB41: 0.985 | AC41: 0.978 | AD41: 0.974 | AE41: 0.985 | AF41: 0.992 | AG41: 0.989 | AH41: 0.993 | AI41: 0.991 | AJ41: 0.994
...

Sheet Chart1

Sheet Chart2

Sheet Chart3

Sheet Chart4

Sheet Chart5
C3: Foreign Holdings of General Government Debt Securities (% of total) | S3: Domestic Central Bank Holdings of General Government Debt (% of total) | AI3: Domestic Bank Holdings of General Government Debt (% of total)
C37: Investorbase of General Government Debt at end-2024Q2 (% of total) | Z37: Foreign Holdings of General Government Debt Securities (% of total)
C56: Italy: Cumulative Net Purchases of General Government Debt by Investor Type, since end-2014 (in billion euros)
AA85: Source: Arslanalp and Tsuda (2014, updated)
AA86: Note: Coverage of debt is general government.

Sheet Table 1. Total
A1: Billion LC | B1: 2004Q1 | C1: 2004Q2 | D1: 2004Q3 | E1: 2004Q4 | F1: 2005Q1 | G1: 2005Q2 | H1: 2005Q3 | I1: 2005Q4 | J1: 2006Q1 | K1: 2006Q2 | L1: 2006Q3 | M1: 2006Q4 | N1: 2007Q1 | O1: 2007Q2 | P1: 2007Q3 | Q1: 2007Q4 | R1: 2008Q1 | S1: 2008Q2 | T1: 2008Q3 | U1: 2008Q4 | V1: 2009Q1 | W1: 2009Q2 | X1: 2009Q3 | Y1: 2009Q4 | Z1: 2010Q1 | AA1: 2010Q2 | AB1: 2010Q3 | AC1: 2010Q4 | AD1: 2011Q1 | AE1: 2011Q2 | AF1: 2011Q3 | AG1: 2011Q4 | AH1: 2012Q1 | AI1: 2012Q2 | AJ1: 2012Q3 | AK1: 2012Q4 | AL1: 2013Q1 | AM1: 2013Q2 | AN1: 2013Q3 | AO1: 2013Q4 | AP1: 2014Q1 | AQ1: 2014Q2 | AR1: 2014Q3 | AS1: 2014Q4 | AT1: 2015Q1 | AU1: 2015Q2 | AV1: 2015Q3 | AW1: 2015Q4 | AX1: 2016Q1 | AY1: 2016Q2 | AZ1: 2016Q3 | BA1: 2016Q4 | BB1: 2017Q1 | BC1: 2017Q2 | BD1: 2017Q3 | BE1: 2017Q4 | BF1: 2018Q1 | BG1: 2018Q2 | BH1: 2018Q3 | BI1: 2018Q4 | BJ1: 2019Q1 | BK1: 2019Q2 | BL1: 2019Q3 | BM1: 2019Q4 | BN1: 2020Q1 | BO1: 2020Q2 | BP1: 2020Q3 | BQ1: 2020Q4 | BR1: 2021Q1 | BS1: 2021Q2 | BT1: 2021Q3 | BU1: 2021Q4 | BV1: 2022Q1 | BW1: 2022Q2 | BX1: 2022Q3 | BY1: 2022Q4 | BZ1: 2023Q1 | CA1: 2023Q2 | CB1: 2023Q3 | CC1: 2023Q4 | CD1: 2024Q1 | CE1: 2024Q2
A2: Australia | B2: 99.676 | C2: 98.403 | D2: 99.463 | E2: 98.371 | F2: 99.262 | G2: 97.174 | H2: 96.75 | I2: 95.67 | J2: 94.639 | K2: 95.197 | L2: 95.502 | M2: 94.371 | N2: 92.995 | O2: 95.899 | P2: 101.526 | Q2: 101.98 | R2: 101.759 | S2: 114.656 | T2: 125.629 | U2: 139.455 | V2: 149.703 | W2: 162.82 | X2: 186.006 | Y2: 197.87 | Z2: 214.904 | AA2: 229.823 | AB2: 244.952 | AC2: 255.388 | AD2: 273.961 | AE2: 294.588 | AF2: 312.671 | AG2: 327.225 | AH2: 340.169 | AI2: 362.1 | AJ2: 377.627 | AK2: 381.15 | AL2: 389.338 | AM2: 397.307 | AN2: 419.97 | AO2: 439.698 | AP2: 458.971 | AQ2: 474.4 | AR2: 491.591 | AS2: 503.236 | AT2: 517.309 | AU2: 528.797 | AV2: 548.925 | AW2: 559.156 | AX2: 572.106 | AY2: 583.194 | AZ2: 605.526 | BA2: 621.359 | BB2: 639.415 | BC2: 661.452 | BD2: 672.99 | BE2: 682.677 | BF2: 691.91 | BG2: 699.904 | BH2: 704.69 | BI2: 711.617 | BJ2: 716.729 | BK2: 723.689 | BL2: 767.143 | BM2: 811.364 | BN2: 862.372 | BO2: 927.777 | BP2: 987.103 | BQ2: 1039.316 | BR2: 1077.043 | BS2: 1116.087 | BT2: 1158.795 | BU2: 1185.387 | BV2: 1204.273 | BW2: 1245.724 | BX2: 1262.723 | BY2: 1268.571 | BZ2: 1272.151 | CA2: 1280.691 | CB2: 1292.84 | CC2: 1313.062 | CD2: 1327.979 | CE2: 1342.26
A3: Austria | B3: 160.907 | C3: 169.004 | D3: 171.083 | E3: 158.546 | F3: 180.542 | G3: 188.732 | H3: 189.145 | I3: 175.204 | J3: 185.166 | K3: 193.804 | L3: 188.695 | M3: 181.304 | N3: 194.673 | O3: 203.676 | P3: 211.968 | Q3: 185.73 | R3: 192.286 | S3: 194.074 | T3: 196.299 | U3: 202.915 | V3: 212.254 | W3: 216.304 | X3: 212.632 | Y3: 231.173 | Z3: 233.802 | AA3: 243.545 | AB3: 245.742 | AC3: 245.985 | AD3: 249.003 | AE3: 251.625 | AF3: 253.177 | AG3: 256.876 | AH3: 261.102 | AI3: 265.899 | AJ3: 262.298 | AK3: 262.565 | AL3: 266.258 | AM3: 266.259 | AN3: 272.356 | AO3: 264.761 | AP3: 266.667 | AQ3: 272.153 | AR3: 268.627 | AS3: 281.289 | AT3: 285.598 | AU3: 291.121 | AV3: 293.893 | AW3: 292.874 | AX3: 298.885 | AY3: 298.679 | AZ3: 292.186 | BA3: 296.693 | BB3: 293.018 | BC3: 295.024 | BD3: 293.451 | BE3: 290.373 | BF3: 289.638 | BG3: 289.982 | BH3: 289.251 | BI3: 285.84 | BJ3: 283.587 | BK3: 282.42 | BL3: 281.964 | BM3: 280.975 | BN3: 289.889 | BO3: 316.714 | BP3: 301.253 | BQ3: 316.36 | BR3: 327.899 | BS3: 335.38 | BT3: 333.64 | BU3: 334.713 | BV3: 349.278 | BW3: 355.292 | BX3: 356.297 | BY3: 351.129 | BZ3: 368.358 | CA3: 366.445 | CB3: 369.771 | CC3: 371.729 | CD3: 383.713 | CE3: 394.78
